<?xml version="1.0" ?>
<!-- =================================================================================== -->
<!-- |    This document was autogenerated by xacro from urdf/irb4600_60_205.xacro      | -->
<!-- |    EDITING THIS FILE BY HAND IS NOT RECOMMENDED                                 | -->
<!-- =================================================================================== -->
<robot name="abb_irb4600_60_205">
  <!-- link list -->

  <link name="chassis">
    <inertial>
      <mass value="10.0"/>
      <inertia ixx="0.095329" ixy="0.0" ixz="0.0" iyy="0.381317" iyz="0.0" izz="0.476646"/>
    </inertial>
    
    <visual name="visual">
        <geometry>
            <box size="2.0 1.0 0.5"/>
        </geometry>
        <material name="blue">
            <color rgba="0.0 0.0 1.0 1"/>
        </material>
    </visual>

    <collision name="collision">
        <geometry>
            <box size="2.0 1.0 0.5"/>
        </geometry>
    </collision>
  </link>
  <link name="left_wheel">
      <inertial>
          <mass value="1"/>
          <inertia ixx="0.043333" ixy="0.0" ixz="0.0" iyy="0.043333" iyz="0.0" izz="0.08"/>
      </inertial>
      <visual>
          <geometry>
              <cylinder radius="0.4" length="0.2"/>
          </geometry>
          <material name="red">
              <color rgba="1.0 0.0 0.0 1"/>
          </material>
      </visual>
      <collision>
          <geometry>
              <cylinder radius="0.4" length="0.2"/>
          </geometry>
      </collision>
  </link>
  <link name="right_wheel">
      <inertial>
          <mass value="1"/>
          <inertia ixx="0.043333" ixy="0.0" ixz="0.0" iyy="0.043333" iyz="0.0" izz="0.08"/>
      </inertial>
      <visual>
          <geometry>
              <cylinder radius="0.4" length="0.2"/>
          </geometry>
          <material name="red">
              <color rgba="1.0 0.0 0.0 1"/>
          </material>
      </visual>
      <collision>
          <geometry>
              <cylinder radius="0.4" length="0.2"/>
          </geometry>
      </collision>
  </link>
  <link name="caster_pitch">
      <inertial>
          <mass value="0.01"/>
          <inertia ixx="0.0001" ixy="0.0" ixz="0.0" iyy="0.0001" iyz="0.0" izz="0.0001"/>
      </inertial>
      <visual>
          <geometry>
              <sphere radius="0.01"/> 
          </geometry>
          <material name="red">
              <color rgba="0.0 0.0 0.0 0"/>
          </material>
      </visual>
      <collision>
          <geometry>
              <sphere radius="0.01"/>
          </geometry>
      </collision>
  </link>
  <link name="caster_roll">
      <inertial>
          <mass value="0.01"/>
          <inertia ixx="0.0001" ixy="0.0" ixz="0.0" iyy="0.0001" iyz="0.0" izz="0.0001"/>
      </inertial>
      <visual>
          <geometry>
              <sphere radius="0.01"/>
          </geometry>
          <material name="red">
              <color rgba="0.0 0.0 0.0 0"/>
          </material>
      </visual>
      <collision>
          <geometry>
              <sphere radius="0.01"/>
          </geometry>
      </collision>
  </link>
  <link name="caster">
      <inertial>
          <mass value="1"/>
          <inertia ixx="0.016" ixy="0.0" ixz="0.0" iyy="0.016" iyz="0.0" izz="0.016"/>
      </inertial>
      <visual>
          <geometry>
              <sphere radius="0.2"/>
          </geometry>
          <material name="red">
              <color rgba="0.0 1.0 0.0 1"/>
          </material>
      </visual>
      <collision>
          <geometry>
              <sphere radius="0.2"/>
          </geometry>
      </collision>
  </link>

  <!-- end of link list -->
  <!-- joint list -->
  <joint name="left_wheel_joint" type="revolute">
    <parent link="chassis"/>
    <child link="left_wheel"/>
    <origin xyz="-0.5 0.7 0" rpy="-1.5707 0 0"/>
    <axis xyz="0 0 1"/>
    <limit effort="1000.0" lower="-1.79769e+308" upper="1.79769e+308" velocity="30.0"/>
    <dynamics damping="0.3" friction="0.0"/>
  </joint>
  <joint name="right_wheel_joint" type="revolute">
    <parent link="chassis"/>
    <child link="right_wheel"/>
    <origin xyz="-0.5 -0.7 0" rpy="-1.5707 0 0"/>
    <axis xyz="0 0 1"/>
    <limit effort="1000.0" lower="-1.79769e+308" upper="1.79769e+308" velocity="30.0"/>
    <dynamics damping="0.3" friction="0.0"/>
  </joint>
  <joint name="caster_pitch_joint" type="revolute">
      <parent link="chassis"/>
      <child link="caster_pitch"/>
      <origin xyz="0.8 0 -0.2" rpy="0 0 0"/>
      <axis xyz="1 0 0"/>
      <limit lower="-1.79769e+308" upper="1.79769e+308" effort="50" velocity="5"/>
  </joint>
  <joint name="caster_roll_joint" type="revolute">
      <parent link="caster_pitch"/>
      <child link="caster_roll"/>
      <origin xyz="0 0 0"/>
      <axis xyz="0 1 0"/>
      <limit lower="-1.79769e+308" upper="1.79769e+308" effort="50" velocity="5"/>
  </joint>
  <joint name="caster_spin_joint" type="revolute">
      <parent link="caster_roll"/>
      <child link="caster"/>
      <origin xyz="0 0 0"/>
      <axis xyz="0 0 1"/>
      <limit lower="-1.79769e+308" upper="1.79769e+308" effort="50" velocity="5"/>
  </joint>

  <gazebo>
    <!-- <plugin filename="ign_ros2_control-system" name="ign_ros2_control::IgnitionROS2ControlPlugin">
      <parameters>/home/yangjingyun/robots/ros2_simulation/src/warehouse_manage/config/abb_irb4600_60_205.yaml</parameters>
    </plugin> -->
    
    <plugin
      filename="gz-sim-diff-drive-system"
      name="gz::sim::systems::DiffDrive">
      <left_joint>left_wheel_joint</left_joint>
      <right_joint>right_wheel_joint</right_joint>
      <wheel_separation>1.2</wheel_separation>
      <wheel_radius>0.4</wheel_radius>
      <odom_publish_frequency>1</odom_publish_frequency>
      <topic>cmd_vel</topic>
    </plugin>

    <plugin filename="gz-sim-triggered-publisher-system"
        name="gz::sim::systems::TriggeredPublisher">
      <input type="gz.msgs.Int32" topic="/keyboard/keypress">
          <match field="data">16777235</match>
      </input>
      <output type="gz.msgs.Twist" topic="/cmd_vel">
          linear: {x: 1.0}, angular: {z: 0.0}
      </output>
    </plugin>
    <plugin filename="gz-sim-triggered-publisher-system"
            name="gz::sim::systems::TriggeredPublisher">
      <input type="gz.msgs.Int32" topic="/keyboard/keypress">
          <match field="data">16777237</match>
      </input>
      <output type="gz.msgs.Twist" topic="/cmd_vel">
          linear: {x: -1.0}, angular: {z: 0.0}
      </output>
    </plugin>
    <plugin filename="gz-sim-triggered-publisher-system"
            name="gz::sim::systems::TriggeredPublisher">
      <input type="gz.msgs.Int32" topic="/keyboard/keypress">
          <match field="data">16777234</match>
      </input>
      <output type="gz.msgs.Twist" topic="/cmd_vel">
          linear: {x: 0.0}, angular: {z: 0.5}
      </output>
    </plugin>
    <plugin filename="gz-sim-triggered-publisher-system"
            name="gz::sim::systems::TriggeredPublisher">
      <input type="gz.msgs.Int32" topic="/keyboard/keypress">
          <match field="data">16777236</match>
      </input>
      <output type="gz.msgs.Twist" topic="/cmd_vel">
          linear: {x: 0.0}, angular: {z: -0.5}
      </output>
    </plugin>
        <plugin filename="gz-sim-triggered-publisher-system"
            name="gz::sim::systems::TriggeredPublisher">
      <input type="gz.msgs.Int32" topic="/keyboard/keypress">
          <match field="data">83</match>
      </input>
      <output type="gz.msgs.Twist" topic="/cmd_vel">
          linear: {x: 0.0}, angular: {z: 0.0}
      </output>
    </plugin>
  </gazebo>
</robot>
