<sdf version='1.11'>
  <model name='abb_irb4600_60_205'>
    <link name='base_link'>
      <inertial>
        <pose>0 0 0 0 0 0</pose>
        <mass>10</mass>
        <inertia>
          <ixx>0.20830000000000001</ixx>
          <ixy>0</ixy>
          <ixz>0</ixz>
          <iyy>0.20830000000000001</iyy>
          <iyz>0</iyz>
          <izz>0.33329999999999999</izz>
        </inertia>
      </inertial>
      <collision name='base_link_fixed_joint_lump__collision_collision'>
        <pose>0 0 0 0 0 0</pose>
        <geometry>
          <mesh>
            <scale>1 1 1</scale>
            <uri>model://abb_irb4600_support/meshes/irb4600/collision/base_link.stl</uri>
          </mesh>
        </geometry>
      </collision>
      <visual name='base_link_fixed_joint_lump__visual_visual'>
        <pose>0 0 0 0 0 0</pose>
        <geometry>
          <mesh>
            <scale>1 1 1</scale>
            <uri>model://abb_irb4600_support/meshes/irb4600/visual/base_link.dae</uri>
          </mesh>
        </geometry>
        <material>
          <diffuse>1 1 0 1</diffuse>
          <ambient>1 1 0 1</ambient>
        </material>
      </visual>
    </link>
    <joint name='joint_1' type='revolute'>
      <pose relative_to='base_link'>0 0 0.495 0 0 0</pose>
      <parent>base_link</parent>
      <child>link_1</child>
      <axis>
        <xyz>0 0 1</xyz>
        <limit>
          <lower>-15</lower>
          <upper>15</upper>
          <effort>1000</effort>
          <velocity>30</velocity>
        </limit>
        <dynamics>
          <damping>1</damping>
          <friction>100</friction>
          <spring_reference>0</spring_reference>
          <spring_stiffness>0</spring_stiffness>
        </dynamics>
      </axis>
    </joint>
    <link name='link_1'>
      <pose relative_to='joint_1'>0 0 0 0 0 0</pose>
      <inertial>
        <pose>0 0 0 0 0 0</pose>
        <mass>1</mass>
        <inertia>
          <ixx>0.20830000000000001</ixx>
          <ixy>0</ixy>
          <ixz>0</ixz>
          <iyy>0.20830000000000001</iyy>
          <iyz>0</iyz>
          <izz>0.33329999999999999</izz>
        </inertia>
      </inertial>
      <collision name='link_1_fixed_joint_lump__collision_collision'>
        <pose>0 0 0 0 0 0</pose>
        <geometry>
          <mesh>
            <scale>1 1 1</scale>
            <uri>model://abb_irb4600_support/meshes/irb4600/collision/link_1.stl</uri>
          </mesh>
        </geometry>
      </collision>
      <visual name='link_1_fixed_joint_lump__visual_visual'>
        <pose>0 0 0 0 0 0</pose>
        <geometry>
          <mesh>
            <scale>1 1 1</scale>
            <uri>model://abb_irb4600_support/meshes/irb4600/visual/link_1.dae</uri>
          </mesh>
        </geometry>
        <material>
          <diffuse>1 1 0 1</diffuse>
          <ambient>1 1 0 1</ambient>
        </material>
      </visual>
    </link>
    <joint name='joint_2' type='revolute'>
      <pose relative_to='link_1'>0.17499999999999999 0 0 0 0 0</pose>
      <parent>link_1</parent>
      <child>link_2</child>
      <axis>
        <xyz>0 1 0</xyz>
        <limit>
          <lower>-15</lower>
          <upper>15</upper>
          <effort>1000</effort>
          <velocity>30</velocity>
        </limit>
        <dynamics>
          <damping>1</damping>
          <friction>100</friction>
          <spring_reference>0</spring_reference>
          <spring_stiffness>0</spring_stiffness>
        </dynamics>
      </axis>
    </joint>
    <link name='link_2'>
      <pose relative_to='joint_2'>0 0 0 0 0 0</pose>
      <inertial>
        <pose>0 0 0 0 0 0</pose>
        <mass>1</mass>
        <inertia>
          <ixx>0.20830000000000001</ixx>
          <ixy>0</ixy>
          <ixz>0</ixz>
          <iyy>0.20830000000000001</iyy>
          <iyz>0</iyz>
          <izz>0.33329999999999999</izz>
        </inertia>
      </inertial>
      <collision name='link_2_fixed_joint_lump__collision_collision'>
        <pose>0 0 0 0 0 0</pose>
        <geometry>
          <mesh>
            <scale>1 1 1</scale>
            <uri>model://abb_irb4600_support/meshes/irb4600_60_205/collision/link_2.stl</uri>
          </mesh>
        </geometry>
      </collision>
      <visual name='link_2_fixed_joint_lump__visual_visual'>
        <pose>0 0 0 0 0 0</pose>
        <geometry>
          <mesh>
            <scale>1 1 1</scale>
            <uri>model://abb_irb4600_support/meshes/irb4600_60_205/visual/link_2.dae</uri>
          </mesh>
        </geometry>
        <material>
          <diffuse>1 1 0 1</diffuse>
          <ambient>1 1 0 1</ambient>
        </material>
      </visual>
    </link>
    <joint name='joint_3' type='revolute'>
      <pose relative_to='link_2'>0 0 0.90000000000000002 0 0 0</pose>
      <parent>link_2</parent>
      <child>link_3</child>
      <axis>
        <xyz>0 1 0</xyz>
        <limit>
          <lower>-15</lower>
          <upper>15</upper>
          <effort>1000</effort>
          <velocity>30</velocity>
        </limit>
        <dynamics>
          <damping>1</damping>
          <friction>100</friction>
          <spring_reference>0</spring_reference>
          <spring_stiffness>0</spring_stiffness>
        </dynamics>
      </axis>
    </joint>
    <link name='link_3'>
      <pose relative_to='joint_3'>0 0 0 0 0 0</pose>
      <inertial>
        <pose>0 0 0 0 0 0</pose>
        <mass>1</mass>
        <inertia>
          <ixx>0.20830000000000001</ixx>
          <ixy>0</ixy>
          <ixz>0</ixz>
          <iyy>0.20830000000000001</iyy>
          <iyz>0</iyz>
          <izz>0.33329999999999999</izz>
        </inertia>
      </inertial>
      <collision name='link_3_fixed_joint_lump__collision_collision'>
        <pose>0 0 0 0 0 0</pose>
        <geometry>
          <mesh>
            <scale>1 1 1</scale>
            <uri>model://abb_irb4600_support/meshes/irb4600_60_205/collision/link_3.stl</uri>
          </mesh>
        </geometry>
      </collision>
      <visual name='link_3_fixed_joint_lump__visual_visual'>
        <pose>0 0 0 0 0 0</pose>
        <geometry>
          <mesh>
            <scale>1 1 1</scale>
            <uri>model://abb_irb4600_support/meshes/irb4600_60_205/visual/link_3.dae</uri>
          </mesh>
        </geometry>
        <material>
          <diffuse>1 1 0 1</diffuse>
          <ambient>1 1 0 1</ambient>
        </material>
      </visual>
    </link>
    <joint name='joint_4' type='revolute'>
      <pose relative_to='link_3'>0 0 0.17499999999999999 0 0 0</pose>
      <parent>link_3</parent>
      <child>link_4</child>
      <axis>
        <xyz>1 0 0</xyz>
        <limit>
          <lower>-15</lower>
          <upper>15</upper>
          <effort>1000</effort>
          <velocity>30</velocity>
        </limit>
        <dynamics>
          <damping>1</damping>
          <friction>100</friction>
          <spring_reference>0</spring_reference>
          <spring_stiffness>0</spring_stiffness>
        </dynamics>
      </axis>
    </joint>
    <link name='link_4'>
      <pose relative_to='joint_4'>0 0 0 0 0 0</pose>
      <inertial>
        <pose>0 0 0 0 0 0</pose>
        <mass>1</mass>
        <inertia>
          <ixx>0.20830000000000001</ixx>
          <ixy>0</ixy>
          <ixz>0</ixz>
          <iyy>0.20830000000000001</iyy>
          <iyz>0</iyz>
          <izz>0.33329999999999999</izz>
        </inertia>
      </inertial>
      <collision name='link_4_fixed_joint_lump__collision_collision'>
        <pose>0 0 0 0 0 0</pose>
        <geometry>
          <mesh>
            <scale>1 1 1</scale>
            <uri>model://abb_irb4600_support/meshes/irb4600_60_205/collision/link_4.stl</uri>
          </mesh>
        </geometry>
      </collision>
      <visual name='link_4_fixed_joint_lump__visual_visual'>
        <pose>0 0 0 0 0 0</pose>
        <geometry>
          <mesh>
            <scale>1 1 1</scale>
            <uri>model://abb_irb4600_support/meshes/irb4600_60_205/visual/link_4.dae</uri>
          </mesh>
        </geometry>
        <material>
          <diffuse>1 1 0 1</diffuse>
          <ambient>1 1 0 1</ambient>
        </material>
      </visual>
    </link>
    <joint name='joint_5' type='revolute'>
      <pose relative_to='link_4'>0.95999999999999996 0 0 0 0 0</pose>
      <parent>link_4</parent>
      <child>link_5</child>
      <axis>
        <xyz>0 1 0</xyz>
        <limit>
          <lower>-15</lower>
          <upper>15</upper>
          <effort>1000</effort>
          <velocity>30</velocity>
        </limit>
        <dynamics>
          <damping>1</damping>
          <friction>0</friction>
          <spring_reference>0</spring_reference>
          <spring_stiffness>0</spring_stiffness>
        </dynamics>
      </axis>
    </joint>
    <link name='link_5'>
      <pose relative_to='joint_5'>0 0 0 0 0 0</pose>
      <inertial>
        <pose>0 0 0 0 0 0</pose>
        <mass>1</mass>
        <inertia>
          <ixx>0.20830000000000001</ixx>
          <ixy>0</ixy>
          <ixz>0</ixz>
          <iyy>0.20830000000000001</iyy>
          <iyz>0</iyz>
          <izz>0.33329999999999999</izz>
        </inertia>
      </inertial>
      <collision name='link_5_fixed_joint_lump__collision_collision'>
        <pose>0 0 0 0 0 0</pose>
        <geometry>
          <mesh>
            <scale>1 1 1</scale>
            <uri>model://abb_irb4600_support/meshes/irb4600_60_205/collision/link_5.stl</uri>
          </mesh>
        </geometry>
      </collision>
      <visual name='link_5_fixed_joint_lump__visual_visual'>
        <pose>0 0 0 0 0 0</pose>
        <geometry>
          <mesh>
            <scale>1 1 1</scale>
            <uri>model://abb_irb4600_support/meshes/irb4600_60_205/visual/link_5.dae</uri>
          </mesh>
        </geometry>
        <material>
          <diffuse>1 1 0 1</diffuse>
          <ambient>1 1 0 1</ambient>
        </material>
      </visual>
    </link>
    <joint name='joint_6' type='revolute'>
      <pose relative_to='link_5'>0.13500000000000001 0 0 0 0 0</pose>
      <parent>link_5</parent>
      <child>link_6</child>
      <axis>
        <xyz>1 0 0</xyz>
        <limit>
          <lower>-15</lower>
          <upper>15</upper>
          <effort>1000</effort>
          <velocity>30</velocity>
        </limit>
        <dynamics>
          <damping>1</damping>
          <friction>100</friction>
          <spring_reference>0</spring_reference>
          <spring_stiffness>0</spring_stiffness>
        </dynamics>
      </axis>
    </joint>
    <link name='link_6'>
      <pose relative_to='joint_6'>0 0 0 0 0 0</pose>
      <inertial>
        <pose>0 0 0 0 0 0</pose>
        <mass>3</mass>
        <inertia>
          <ixx>0.74990000000000001</ixx>
          <ixy>0</ixy>
          <ixz>7.654042494670956e-18</ixz>
          <iyy>0.62490000000000001</iyy>
          <iyz>0</iyz>
          <izz>0.87490000000000001</izz>
        </inertia>
      </inertial>
      <collision name='link_6_fixed_joint_lump__collision_collision'>
        <pose>0 0 0 0 0 0</pose>
        <geometry>
          <mesh>
            <scale>1 1 1</scale>
            <uri>model://abb_irb4600_support/meshes/irb4600_60_205/collision/link_6.stl</uri>
          </mesh>
        </geometry>
      </collision>
      <collision name='link_6_fixed_joint_lump__flange_collision_1'>
        <pose>0 0 0 0 0 0</pose>
        <geometry>
          <box>
            <size>0.001 0.001 0.001</size>
          </box>
        </geometry>
      </collision>
      <collision name='link_6_fixed_joint_lump__tool_0_collision_2'>
        <pose>0 0 0 0 1.5707963267948966 0</pose>
        <geometry>
          <box>
            <size>0.050000000000000003 0.050000000000000003 0.050000000000000003</size>
          </box>
        </geometry>
      </collision>
      <visual name='link_6_fixed_joint_lump__visual_visual'>
        <pose>0 0 0 0 0 0</pose>
        <geometry>
          <mesh>
            <scale>1 1 1</scale>
            <uri>model://abb_irb4600_support/meshes/irb4600_60_205/visual/link_6.dae</uri>
          </mesh>
        </geometry>
        <material>
          <diffuse>1 1 0 1</diffuse>
          <ambient>1 1 0 1</ambient>
        </material>
      </visual>
      <visual name='link_6_fixed_joint_lump__flange_visual_1'>
        <pose>0 0 0 0 0 0</pose>
        <geometry>
          <box>
            <size>0.001 0.001 0.001</size>
          </box>
        </geometry>
      </visual>
      <visual name='link_6_fixed_joint_lump__tool_0_visual_2'>
        <pose>0 0 0 0 1.5707963267948966 0</pose>
        <geometry>
          <box>
            <size>0.050000000000000003 0.050000000000000003 0.050000000000000003</size>
          </box>
        </geometry>
      </visual>
    </link>
    <plugin name='gz_ros2_control::GazeboSimROS2ControlPlugin' filename='gz_ros2_control-system'>
      <parameters>/home/yjy/astar_proj/ros2_simulation/src/warehouse_manage/config/abb_irb4600_60_205.yaml</parameters>
    </plugin>
    <plugin name='gz::sim::systems::DetachableJoint' filename='gz-sim-detachable-joint-system'>
      <parent_link>tool_0</parent_link>
      <child_model>box</child_model>
      <child_link>base_link</child_link>
      <detach_topic>/B1/detach</detach_topic>
      <attach_topic>/B1/attach</attach_topic>
      <output_topic>/B1/state</output_topic>
    </plugin>
    <frame name='link_6-tool0' attached_to='flange'>
      <pose>0 0 0 0 1.5707963267948966 0</pose>
    </frame>
    <frame name='tool_0' attached_to='link_6-tool0'>
      <pose>0 0 0 0 0 0</pose>
    </frame>
    <frame name='joint_6-flange' attached_to='link_6'>
      <pose>0 0 0 0 0 0</pose>
    </frame>
    <frame name='flange' attached_to='joint_6-flange'>
      <pose>0 0 0 0 0 0</pose>
    </frame>
  </model>
</sdf>
