<?xml version="1.0" ?>
<!-- =================================================================================== -->
<!-- |    This document was autogenerated by xacro from urdf/irb4600_60_205.xacro      | -->
<!-- |    EDITING THIS FILE BY HAND IS NOT RECOMMENDED                                 | -->
<!-- =================================================================================== -->
<robot name="abb_irb4600_60_205">
  <!-- link list -->
  
  <!-- <link name="world"/> -->

  <link name="chassis">
    <inertial>
      <mass value="10.0"/>
      <inertia ixx="0.095329" ixy="0.0" ixz="0.0" iyy="0.381317" iyz="0.0" izz="0.476646"/>
    </inertial>
    
    <visual name="visual">
        <geometry>
            <box size="2.0 1.0 0.5"/>
        </geometry>
        <material name="blue">
            <color rgba="0.0 0.0 1.0 1"/>
        </material>
    </visual>

    <collision name="collision">
        <geometry>
            <box size="2.0 1.0 0.5"/>
        </geometry>
    </collision>
  </link>
  <link name="left_wheel">
      <inertial>
          <mass value="1"/>
          <inertia ixx="0.043333" ixy="0.0" ixz="0.0" iyy="0.043333" iyz="0.0" izz="0.08"/>
      </inertial>
      <visual>
          <geometry>
              <cylinder radius="0.4" length="0.2"/>
          </geometry>
          <material name="red">
              <color rgba="1.0 0.0 0.0 1"/>
          </material>
      </visual>
      <collision>
          <geometry>
              <cylinder radius="0.4" length="0.2"/>
          </geometry>
      </collision>
  </link>
  <link name="right_wheel">
      <inertial>
          <mass value="1"/>
          <inertia ixx="0.043333" ixy="0.0" ixz="0.0" iyy="0.043333" iyz="0.0" izz="0.08"/>
      </inertial>
      <visual>
          <geometry>
              <cylinder radius="0.4" length="0.2"/>
          </geometry>
          <material name="red">
              <color rgba="1.0 0.0 0.0 1"/>
          </material>
      </visual>
      <collision>
          <geometry>
              <cylinder radius="0.4" length="0.2"/>
          </geometry>
      </collision>
  </link>
<!-- Caster Pitch Intermediate Link -->
  <link name="caster_pitch">
      <inertial>
          <mass value="0.01"/>
          <inertia ixx="0.0001" ixy="0.0" ixz="0.0" iyy="0.0001" iyz="0.0" izz="0.0001"/>
      </inertial>
      <visual>
          <geometry>
              <sphere radius="0.01"/> <!-- Small dummy geometry -->
          </geometry>
          <material>
              <color rgba="0.0 0.0 0.0 0"/>
          </material>
      </visual>
      <collision>
          <geometry>
              <sphere radius="0.01"/>
          </geometry>
      </collision>
  </link>
  <!-- Caster Roll Intermediate Link -->
  <link name="caster_roll">
      <inertial>
          <mass value="0.01"/>
          <inertia ixx="0.0001" ixy="0.0" ixz="0.0" iyy="0.0001" iyz="0.0" izz="0.0001"/>
      </inertial>
      <visual>
          <geometry>
              <sphere radius="0.01"/>
          </geometry>
          <material>
              <color rgba="0.0 0.0 0.0 0"/>
          </material>
      </visual>
      <collision>
          <geometry>
              <sphere radius="0.01"/>
          </geometry>
      </collision>
  </link>

  <link name="caster">
      <inertial>
          <mass value="1"/>
          <inertia ixx="0.016" ixy="0.0" ixz="0.0" iyy="0.016" iyz="0.0" izz="0.016"/>
      </inertial>
      <visual>
          <geometry>
              <sphere radius="0.2"/>
          </geometry>
          <material name="red">
              <color rgba="0.0 1.0 0.0 1"/>
          </material>
      </visual>
      <collision>
          <geometry>
              <sphere radius="0.2"/>
          </geometry>
      </collision>
  </link>

  <link name="base_link">
    <collision name="collision">
      <geometry>
        <mesh filename="package://abb_irb4600_support/meshes/irb4600/collision/base_link.stl"/>
      </geometry>
    </collision>
    <visual name="visual">
      <geometry>
        <mesh filename="package://abb_irb4600_support/meshes/irb4600/visual/base_link.dae"/>
      </geometry>
      <material name="yellow">
        <color rgba="1 1 0 1"/>
      </material>
    </visual>
    <inertial>
      <mass value="10.0" />
      <inertia ixx="0.2083" ixy="0.0" ixz="0.0" iyy="0.2083" iyz="0.0" izz="0.3333"/>
    </inertial>
  </link>
  <link name="link_1">
    <collision name="collision">
      <geometry>
        <mesh filename="package://abb_irb4600_support/meshes/irb4600/collision/link_1.stl"/>
      </geometry>
    </collision>
    <visual name="visual">
      <geometry>
        <mesh filename="package://abb_irb4600_support/meshes/irb4600/visual/link_1.dae"/>
      </geometry>
      <material name="yellow"/>
    </visual>
    <inertial>
      <mass value="1.0" />
      <inertia ixx="0.2083" ixy="0.0" ixz="0.0" iyy="0.2083" iyz="0.0" izz="0.3333"/>
    </inertial>
  </link>
  <link name="link_2">
    <collision name="collision">
      <geometry>
        <mesh filename="package://abb_irb4600_support/meshes/irb4600_60_205/collision/link_2.stl"/>
      </geometry>
    </collision>
    <visual name="visual">
      <geometry>
        <mesh filename="package://abb_irb4600_support/meshes/irb4600_60_205/visual/link_2.dae"/>
      </geometry>
      <material name="yellow"/>
    </visual>
    <inertial>
      <mass value="1.0" />
      <inertia ixx="0.2083" ixy="0.0" ixz="0.0" iyy="0.2083" iyz="0.0" izz="0.3333"/>
    </inertial>
  </link>
  <link name="link_3">
    <collision name="collision">
      <geometry>
        <mesh filename="package://abb_irb4600_support/meshes/irb4600_60_205/collision/link_3.stl"/>
      </geometry>
    </collision>
    <visual name="visual">
      <geometry>
        <mesh filename="package://abb_irb4600_support/meshes/irb4600_60_205/visual/link_3.dae"/>
      </geometry>
      <material name="yellow"/>
    </visual>
    <inertial>
      <mass value="1.0" />
      <inertia ixx="0.2083" ixy="0.0" ixz="0.0" iyy="0.2083" iyz="0.0" izz="0.3333"/>
    </inertial>
  </link>
  <link name="link_4">
    <collision name="collision">
      <geometry>
        <mesh filename="package://abb_irb4600_support/meshes/irb4600_60_205/collision/link_4.stl"/>
      </geometry>
    </collision>
    <visual name="visual">
      <geometry>
        <mesh filename="package://abb_irb4600_support/meshes/irb4600_60_205/visual/link_4.dae"/>
      </geometry>
      <material name="yellow"/>
    </visual>
    <inertial>
      <mass value="1.0" />
      <inertia ixx="0.2083" ixy="0.0" ixz="0.0" iyy="0.2083" iyz="0.0" izz="0.3333"/>
    </inertial>
  </link>
  <link name="link_5">
    <collision name="collision">
      <geometry>
        <mesh filename="package://abb_irb4600_support/meshes/irb4600_60_205/collision/link_5.stl"/>
      </geometry>
    </collision>
    <visual name="visual">
      <geometry>
        <mesh filename="package://abb_irb4600_support/meshes/irb4600_60_205/visual/link_5.dae"/>
      </geometry>
      <material name="yellow"/>
    </visual>
    <inertial>
      <mass value="1.0" />
      <inertia ixx="0.2083" ixy="0.0" ixz="0.0" iyy="0.2083" iyz="0.0" izz="0.3333"/>
    </inertial>
  </link>
  <link name="link_6">
    <collision name="collision">
      <geometry>
        <mesh filename="package://abb_irb4600_support/meshes/irb4600_60_205/collision/link_6.stl"/>
      </geometry>
    </collision>
    <visual name="visual">
      <geometry>
        <mesh filename="package://abb_irb4600_support/meshes/irb4600_60_205/visual/link_6.dae"/>
      </geometry>
      <material name="yellow"/>
    </visual>
    <inertial>
      <mass value="1.0" />
      <inertia ixx="0.2083" ixy="0.0" ixz="0.0" iyy="0.2083" iyz="0.0" izz="0.3333"/>
    </inertial>
  </link>
  <!-- end of link list -->
  <!-- joint list -->
  <!-- <joint name="world_to_base" type="fixed">
    <origin rpy="0 0 0" xyz="0 0 1">
    <parent link="world">
    <child link="base_link">
  </joint> -->
  <joint name="left_wheel_joint" type="revolute">
    <parent link="chassis"/>
    <child link="left_wheel"/>
    <origin xyz="-0.5 0.6 0" rpy="-1.5707 0 0"/>
    <axis xyz="0 0 1"/>
    <limit effort="1000.0" lower="-1.79769e+308" upper="1.79769e+308" velocity="30.0"/>
    <dynamics damping="0.3" friction="0.0"/>
  </joint>
  <joint name="right_wheel_joint" type="revolute">
    <parent link="chassis"/>
    <child link="right_wheel"/>
    <origin xyz="-0.5 -0.6 0" rpy="-1.5707 0 0"/>
    <axis xyz="0 0 1"/>
    <limit effort="1000.0" lower="-1.79769e+308" upper="1.79769e+308" velocity="30.0"/>
    <dynamics damping="0.3" friction="0.0"/>
  </joint>
  <joint name="caster_pitch_joint" type="revolute">
      <parent link="chassis"/>
      <child link="caster_pitch"/>
      <origin xyz="0.8 0 -0.2" rpy="0 0 0"/>
      <axis xyz="1 0 0"/>
      <limit lower="-1.79769e+308" upper="1.79769e+308" effort="50" velocity="5"/>
  </joint>
  <joint name="caster_roll_joint" type="revolute">
      <parent link="caster_pitch"/>
      <child link="caster_roll"/>
      <origin xyz="0 0 0"/>
      <axis xyz="0 1 0"/>
      <limit lower="-1.79769e+308" upper="1.79769e+308" effort="50" velocity="5"/>
  </joint>
  <joint name="caster_spin_joint" type="revolute">
      <parent link="caster_roll"/>
      <child link="caster"/>
      <origin xyz="0 0 0"/>
      <axis xyz="0 0 1"/>
      <limit lower="-1.79769e+308" upper="1.79769e+308" effort="50" velocity="5"/>
  </joint>

  <joint name="chassis_to_base" type="fixed">
    <origin rpy="0 0 0" xyz="0 0 0.25"/>
    <parent link="chassis"/>
    <child link="base_link"/>
  </joint>


  <joint name="joint_1" type="revolute">
    <origin rpy="0 0 0" xyz="0 0 0.495"/>
    <axis xyz="0 0 1"/>
    <parent link="base_link"/>
    <child link="link_1"/>
    <limit effort="1000.0" lower="-15.0" upper="15.0" velocity="30.0"/>
    <dynamics damping="1.0" friction="100.0"/>
  </joint>
  <joint name="joint_2" type="revolute">
    <origin rpy="0 0 0" xyz="0.175 0 0"/>
    <axis xyz="0 1 0"/>
    <parent link="link_1"/>
    <child link="link_2"/>
    <limit effort="1000.0" lower="-15.0" upper="15.0" velocity="30.0"/>
    <dynamics damping="1.0" friction="100.0"/>
  </joint>
  <joint name="joint_3" type="revolute">
    <origin rpy="0 0 0" xyz="0 0 0.9"/>
    <axis xyz="0 1 0"/>
    <parent link="link_2"/>
    <child link="link_3"/>
    <limit effort="1000.0" lower="-15.0" upper="15.0" velocity="30.0"/>
    <dynamics damping="1.0" friction="100.0"/>
  </joint>
  <joint name="joint_4" type="revolute">
    <origin rpy="0 0 0" xyz="0 0 0.175"/>
    <axis xyz="1 0 0"/>
    <parent link="link_3"/>
    <child link="link_4"/>
    <limit effort="1000.0" lower="-15.0" upper="15.0" velocity="30.0"/>
    <dynamics damping="1.0" friction="100.0"/>
  </joint>
  <joint name="joint_5" type="revolute">
    <origin rpy="0 0 0" xyz="0.960 0 0 "/>
    <axis xyz="0 1 0"/>
    <parent link="link_4"/>
    <child link="link_5"/>
    <limit effort="1000.0" lower="-15.0" upper="15.0" velocity="30.0"/>
    <dynamics damping="1.0" friction="0.0"/>
  </joint>
  <joint name="joint_6" type="revolute">
    <origin rpy="0 0 0" xyz="0.135 0 0 "/>
    <axis xyz="1 0 0"/>
    <parent link="link_5"/>
    <child link="link_6"/>
    <limit effort="1000.0" lower="-15.0" upper="15.0" velocity="30.0"/>
    <dynamics damping="1.0" friction="100.0"/>
  </joint>
  <!-- end of joint list -->
  <!-- ROS-Industrial 'base' frame: base_link to ABB World Coordinates transform -->
  <link name="base"/>
  <joint name="base_link-base" type="fixed">
    <origin rpy="0 0 0" xyz="0 0 0"/>
    <parent link="base_link"/>
    <child link="base"/>
  </joint>
  <!-- ROS-Industrial 'flange' frame: attachment point for EEF models -->
  <link name="flange"/>
  <joint name="joint_6-flange" type="fixed">
    <origin rpy="0 0 0" xyz="0 0 0"/>
    <parent link="link_6"/>
    <child link="flange"/>
  </joint>
  <!-- ROS-Industrial 'tool0' frame: all-zeros tool frame -->
  <link name="tool0">
    <collision>
      <geometry>
        <box size="0.05 0.05 0.05"/>
      </geometry>
    </collision>
    <visual>
      <geometry>
        <box size="0.05 0.05 0.05"/>
      </geometry>
    </visual>
    <inertial>
      <mass value="1.0" />
      <inertia ixx="0.2083" ixy="0.0" ixz="0.0" iyy="0.2083" iyz="0.0" izz="0.3333"/>
    </inertial>
  </link>
  <joint name="link_6-tool0" type="fixed">
    <origin rpy="0 1.5707963267948966 0" xyz="0 0 0"/>
    <parent link="flange"/>
    <child link="tool0"/>
  </joint>

  <!-- <ros2_control name="GazeboSimSystem" type="system">
    <hardware>
      <plugin>gz_ros2_control/GazeboSimSystem</plugin>
    </hardware> -->
  <ros2_control name="IgnitionSystem" type="system">
    <hardware>
      <plugin>ign_ros2_control/IgnitionSystem</plugin>
    </hardware>
    <!-- Revolute joints -->
    <joint name="joint_1">
      <command_interface name="position">
        <param name="min">-15</param>
        <param name="max">15</param>
      </command_interface>
      <state_interface name="position">
        <param name="initial_value">0.0</param> 
      </state_interface>
      <state_interface name="velocity"/>
      <state_interface name="effort"/>
    </joint>
    <joint name="joint_2">
      <command_interface name="position" />
      <state_interface name="position">
        <param name="initial_value">0.0</param> 
      </state_interface>
      <state_interface name="velocity"/>
      <state_interface name="effort"/>
    </joint>
    <joint name="joint_3">
      <command_interface name="position" />
      <state_interface name="position">
        <param name="initial_value">0.0</param> 
      </state_interface>
      <state_interface name="velocity"/>
      <state_interface name="effort"/>
    </joint>
    <joint name="joint_4">
      <command_interface name="position" />
      <state_interface name="position">
        <param name="initial_value">0.0</param> 
      </state_interface>
      <state_interface name="velocity"/>
      <state_interface name="effort"/>
    </joint>
    <joint name="joint_5">
      <command_interface name="position" />
      <state_interface name="position">
        <param name="initial_value">0.0</param> 
      </state_interface>
      <state_interface name="velocity"/>
      <state_interface name="effort"/>
    </joint>
    <joint name="joint_6">
      <command_interface name="position" />
      <state_interface name="position">
        <param name="initial_value">0.0</param> 
      </state_interface>
      <state_interface name="velocity"/>
      <state_interface name="effort"/>
    </joint>
  </ros2_control>

  <gazebo>  
    <plugin filename="ign_ros2_control-system" name="ign_ros2_control::IgnitionROS2ControlPlugin">
      <parameters>/home/yangjingyun/robots/ros2_simulation/src/warehouse_manage/config/abb_irb4600_60_205.yaml</parameters>
    </plugin>
    
    <plugin
      filename="libignition-gazebo-diff-drive-system.so"
      name="ignition::gazebo::systems::DiffDrive">
      <left_joint>left_wheel_joint</left_joint>
      <right_joint>right_wheel_joint</right_joint>
      <wheel_separation>1.2</wheel_separation>
      <wheel_radius>0.4</wheel_radius>
      <odom_publish_frequency>1</odom_publish_frequency>
      <topic>cmd_vel</topic>
    </plugin>

    <plugin filename="libignition-gazebo-triggered-publisher-system.so"
        name="ignition::gazebo::systems::TriggeredPublisher">
      <input type="ignition.msgs.Int32" topic="/keyboard/keypress">
          <match field="data">16777235</match>
      </input>
      <output type="ignition.msgs.Twist" topic="/cmd_vel">
          linear: {x: 0.5}, angular: {z: 0.0}
      </output>
    </plugin>
    <plugin filename="libignition-gazebo-triggered-publisher-system.so"
            name="ignition::gazebo::systems::TriggeredPublisher">
      <input type="ignition.msgs.Int32" topic="/keyboard/keypress">
          <match field="data">16777237</match>
      </input>
      <output type="ignition.msgs.Twist" topic="/cmd_vel">
          linear: {x: -0.5}, angular: {z: 0.0}
      </output>
    </plugin>
    <plugin filename="libignition-gazebo-triggered-publisher-system.so"
            name="ignition::gazebo::systems::TriggeredPublisher">
      <input type="ignition.msgs.Int32" topic="/keyboard/keypress">
          <match field="data">16777234</match>
      </input>
      <output type="ignition.msgs.Twist" topic="/cmd_vel">
          linear: {x: 0.0}, angular: {z: 0.5}
      </output>
    </plugin>
    <plugin filename="libignition-gazebo-triggered-publisher-system.so"
            name="ignition::gazebo::systems::TriggeredPublisher">
      <input type="ignition.msgs.Int32" topic="/keyboard/keypress">
          <match field="data">16777236</match>
      </input>
      <output type="ignition.msgs.Twist" topic="/cmd_vel">
          linear: {x: 0.0}, angular: {z: -0.5}
      </output>
    </plugin>
        <plugin filename="libignition-gazebo-triggered-publisher-system.so"
            name="ignition::gazebo::systems::TriggeredPublisher">
      <input type="ignition.msgs.Int32" topic="/keyboard/keypress">
          <match field="data">83</match>
      </input>
      <output type="ignition.msgs.Twist" topic="/cmd_vel">
          linear: {x: 0.0}, angular: {z: 0.0}
      </output>
    </plugin>
  </gazebo>
</robot>
