<sdf version='1.9'>
  <model name='abb_irb4600_60_205'>
    <link name='base_link'>
      <inertial>
        <pose>0 0 0 0 0 0</pose>
        <mass>1</mass>
        <inertia>
          <ixx>0.20830000000000001</ixx>
          <ixy>0</ixy>
          <ixz>0</ixz>
          <iyy>0.20830000000000001</iyy>
          <iyz>0</iyz>
          <izz>0.33329999999999999</izz>
        </inertia>
      </inertial>
      <collision name='base_link_fixed_joint_lump__collision_collision'>
        <pose>0 0 0 0 0 0</pose>
        <geometry>
          <mesh>
            <scale>1 1 1</scale>
            <uri>model://abb_irb4600_support/meshes/irb4600/collision/base_link.stl</uri>
          </mesh>
        </geometry>
      </collision>
      <visual name='base_link_fixed_joint_lump__visual_visual'>
        <pose>0 0 0 0 0 0</pose>
        <geometry>
          <mesh>
            <scale>1 1 1</scale>
            <uri>model://abb_irb4600_support/meshes/irb4600/visual/base_link.dae</uri>
          </mesh>
        </geometry>
        <material>
          <diffuse>1 1 0 1</diffuse>
          <ambient>1 1 0 1</ambient>
        </material>
      </visual>
      <gravity>false</gravity>
    </link>
    <joint name='joint_1' type='revolute'>
      <pose relative_to='base_link'>0 0 0.495 0 0 0</pose>
      <parent>base_link</parent>
      <child>link_1</child>
      <axis>
        <xyz>0 0 1</xyz>
        <limit>
          <lower>-3.141</lower>
          <upper>3.141</upper>
          <effort>0</effort>
          <velocity>3.0539999999999998</velocity>
        </limit>
        <dynamics>
          <spring_reference>0</spring_reference>
          <spring_stiffness>0</spring_stiffness>
        </dynamics>
      </axis>
    </joint>
    <link name='link_1'>
      <pose relative_to='joint_1'>0 0 0 0 0 0</pose>
      <inertial>
        <pose>0 0 0 0 0 0</pose>
        <mass>1</mass>
        <inertia>
          <ixx>0.20830000000000001</ixx>
          <ixy>0</ixy>
          <ixz>0</ixz>
          <iyy>0.20830000000000001</iyy>
          <iyz>0</iyz>
          <izz>0.33329999999999999</izz>
        </inertia>
      </inertial>
      <collision name='link_1_fixed_joint_lump__collision_collision'>
        <pose>0 0 0 0 0 0</pose>
        <geometry>
          <mesh>
            <scale>1 1 1</scale>
            <uri>model://abb_irb4600_support/meshes/irb4600/collision/link_1.stl</uri>
          </mesh>
        </geometry>
      </collision>
      <visual name='link_1_fixed_joint_lump__visual_visual'>
        <pose>0 0 0 0 0 0</pose>
        <geometry>
          <mesh>
            <scale>1 1 1</scale>
            <uri>model://abb_irb4600_support/meshes/irb4600/visual/link_1.dae</uri>
          </mesh>
        </geometry>
        <material>
          <diffuse>1 1 0 1</diffuse>
          <ambient>1 1 0 1</ambient>
        </material>
      </visual>
      <gravity>false</gravity>
    </link>
    <joint name='joint_2' type='revolute'>
      <pose relative_to='link_1'>0.175 0 0 0 0 0</pose>
      <parent>link_1</parent>
      <child>link_2</child>
      <axis>
        <xyz>0 1 0</xyz>
        <limit>
          <lower>-1.5700000000000001</lower>
          <upper>2.617</upper>
          <effort>0</effort>
          <velocity>3.0539999999999998</velocity>
        </limit>
        <dynamics>
          <spring_reference>0</spring_reference>
          <spring_stiffness>0</spring_stiffness>
        </dynamics>
      </axis>
    </joint>
    <link name='link_2'>
      <pose relative_to='joint_2'>0 0 0 0 0 0</pose>
      <inertial>
        <pose>0 0 0 0 0 0</pose>
        <mass>1</mass>
        <inertia>
          <ixx>0.20830000000000001</ixx>
          <ixy>0</ixy>
          <ixz>0</ixz>
          <iyy>0.20830000000000001</iyy>
          <iyz>0</iyz>
          <izz>0.33329999999999999</izz>
        </inertia>
      </inertial>
      <collision name='link_2_fixed_joint_lump__collision_collision'>
        <pose>0 0 0 0 0 0</pose>
        <geometry>
          <mesh>
            <scale>1 1 1</scale>
            <uri>model://abb_irb4600_support/meshes/irb4600_60_205/collision/link_2.stl</uri>
          </mesh>
        </geometry>
      </collision>
      <visual name='link_2_fixed_joint_lump__visual_visual'>
        <pose>0 0 0 0 0 0</pose>
        <geometry>
          <mesh>
            <scale>1 1 1</scale>
            <uri>model://abb_irb4600_support/meshes/irb4600_60_205/visual/link_2.dae</uri>
          </mesh>
        </geometry>
        <material>
          <diffuse>1 1 0 1</diffuse>
          <ambient>1 1 0 1</ambient>
        </material>
      </visual>
      <gravity>false</gravity>
    </link>
    <joint name='joint_3' type='revolute'>
      <pose relative_to='link_2'>0 0 0.9 0 0 0</pose>
      <parent>link_2</parent>
      <child>link_3</child>
      <axis>
        <xyz>0 1 0</xyz>
        <limit>
          <lower>-3.141</lower>
          <upper>1.3080000000000001</upper>
          <effort>0</effort>
          <velocity>3.0539999999999998</velocity>
        </limit>
        <dynamics>
          <spring_reference>0</spring_reference>
          <spring_stiffness>0</spring_stiffness>
        </dynamics>
      </axis>
    </joint>
    <link name='link_3'>
      <pose relative_to='joint_3'>0 0 0 0 0 0</pose>
      <inertial>
        <pose>0 0 0 0 0 0</pose>
        <mass>1</mass>
        <inertia>
          <ixx>0.20830000000000001</ixx>
          <ixy>0</ixy>
          <ixz>0</ixz>
          <iyy>0.20830000000000001</iyy>
          <iyz>0</iyz>
          <izz>0.33329999999999999</izz>
        </inertia>
      </inertial>
      <collision name='link_3_fixed_joint_lump__collision_collision'>
        <pose>0 0 0 0 0 0</pose>
        <geometry>
          <mesh>
            <scale>1 1 1</scale>
            <uri>model://abb_irb4600_support/meshes/irb4600_60_205/collision/link_3.stl</uri>
          </mesh>
        </geometry>
      </collision>
      <visual name='link_3_fixed_joint_lump__visual_visual'>
        <pose>0 0 0 0 0 0</pose>
        <geometry>
          <mesh>
            <scale>1 1 1</scale>
            <uri>model://abb_irb4600_support/meshes/irb4600_60_205/visual/link_3.dae</uri>
          </mesh>
        </geometry>
        <material>
          <diffuse>1 1 0 1</diffuse>
          <ambient>1 1 0 1</ambient>
        </material>
      </visual>
      <gravity>false</gravity>
    </link>
    <joint name='joint_4' type='revolute'>
      <pose relative_to='link_3'>0 0 0.175 0 0 0</pose>
      <parent>link_3</parent>
      <child>link_4</child>
      <axis>
        <xyz>1 0 0</xyz>
        <limit>
          <lower>-6.9809999999999999</lower>
          <upper>6.9809999999999999</upper>
          <effort>0</effort>
          <velocity>4.3630000000000004</velocity>
        </limit>
        <dynamics>
          <spring_reference>0</spring_reference>
          <spring_stiffness>0</spring_stiffness>
        </dynamics>
      </axis>
    </joint>
    <link name='link_4'>
      <pose relative_to='joint_4'>0 0 0 0 0 0</pose>
      <inertial>
        <pose>0 0 0 0 0 0</pose>
        <mass>1</mass>
        <inertia>
          <ixx>0.20830000000000001</ixx>
          <ixy>0</ixy>
          <ixz>0</ixz>
          <iyy>0.20830000000000001</iyy>
          <iyz>0</iyz>
          <izz>0.33329999999999999</izz>
        </inertia>
      </inertial>
      <collision name='link_4_fixed_joint_lump__collision_collision'>
        <pose>0 0 0 0 0 0</pose>
        <geometry>
          <mesh>
            <scale>1 1 1</scale>
            <uri>model://abb_irb4600_support/meshes/irb4600_60_205/collision/link_4.stl</uri>
          </mesh>
        </geometry>
      </collision>
      <visual name='link_4_fixed_joint_lump__visual_visual'>
        <pose>0 0 0 0 0 0</pose>
        <geometry>
          <mesh>
            <scale>1 1 1</scale>
            <uri>model://abb_irb4600_support/meshes/irb4600_60_205/visual/link_4.dae</uri>
          </mesh>
        </geometry>
        <material>
          <diffuse>1 1 0 1</diffuse>
          <ambient>1 1 0 1</ambient>
        </material>
      </visual>
      <gravity>false</gravity>
    </link>
    <joint name='joint_5' type='revolute'>
      <pose relative_to='link_4'>0.96 0 0 0 0 0</pose>
      <parent>link_4</parent>
      <child>link_5</child>
      <axis>
        <xyz>0 1 0</xyz>
        <limit>
          <lower>-2.181</lower>
          <upper>2.0939999999999999</upper>
          <effort>0</effort>
          <velocity>4.3630000000000004</velocity>
        </limit>
        <dynamics>
          <spring_reference>0</spring_reference>
          <spring_stiffness>0</spring_stiffness>
        </dynamics>
      </axis>
    </joint>
    <link name='link_5'>
      <pose relative_to='joint_5'>0 0 0 0 0 0</pose>
      <inertial>
        <pose>0 0 0 0 0 0</pose>
        <mass>1</mass>
        <inertia>
          <ixx>0.20830000000000001</ixx>
          <ixy>0</ixy>
          <ixz>0</ixz>
          <iyy>0.20830000000000001</iyy>
          <iyz>0</iyz>
          <izz>0.33329999999999999</izz>
        </inertia>
      </inertial>
      <collision name='link_5_fixed_joint_lump__collision_collision'>
        <pose>0 0 0 0 0 0</pose>
        <geometry>
          <mesh>
            <scale>1 1 1</scale>
            <uri>model://abb_irb4600_support/meshes/irb4600_60_205/collision/link_5.stl</uri>
          </mesh>
        </geometry>
      </collision>
      <visual name='link_5_fixed_joint_lump__visual_visual'>
        <pose>0 0 0 0 0 0</pose>
        <geometry>
          <mesh>
            <scale>1 1 1</scale>
            <uri>model://abb_irb4600_support/meshes/irb4600_60_205/visual/link_5.dae</uri>
          </mesh>
        </geometry>
        <material>
          <diffuse>1 1 0 1</diffuse>
          <ambient>1 1 0 1</ambient>
        </material>
      </visual>
      <gravity>false</gravity>
    </link>
    <joint name='joint_6' type='revolute'>
      <pose relative_to='link_5'>0.135 0 0 0 0 0</pose>
      <parent>link_5</parent>
      <child>link_6</child>
      <axis>
        <xyz>1 0 0</xyz>
        <limit>
          <lower>-6.9809999999999999</lower>
          <upper>6.9809999999999999</upper>
          <effort>0</effort>
          <velocity>6.2830000000000004</velocity>
        </limit>
        <dynamics>
          <spring_reference>0</spring_reference>
          <spring_stiffness>0</spring_stiffness>
        </dynamics>
      </axis>
    </joint>
    <link name='link_6'>
      <pose relative_to='joint_6'>0 0 0 0 0 0</pose>
      <inertial>
        <pose>0 0 0 0 0 0</pose>
        <mass>2</mass>
        <inertia>
          <ixx>0.54159999999999997</ixx>
          <ixy>0</ixy>
          <ixz>7.654042494670956e-18</ixz>
          <iyy>0.41660000000000003</iyy>
          <iyz>0</iyz>
          <izz>0.54159999999999997</izz>
        </inertia>
      </inertial>
      <collision name='link_6_fixed_joint_lump__collision_collision'>
        <pose>0 0 0 0 0 0</pose>
        <geometry>
          <mesh>
            <scale>1 1 1</scale>
            <uri>model://abb_irb4600_support/meshes/irb4600_60_205/collision/link_6.stl</uri>
          </mesh>
        </geometry>
      </collision>
      <collision name='link_6_fixed_joint_lump__tool0_collision_1'>
        <pose>0 0 0 0 1.570796326794897 0</pose>
        <geometry>
          <box>
            <size>0.05 0.05 0.05</size>
          </box>
        </geometry>
        <surface>
          <contact>
            <ode/>
          </contact>
          <friction>
            <ode/>
          </friction>
        </surface>
      </collision>
      <visual name='link_6_fixed_joint_lump__visual_visual'>
        <pose>0 0 0 0 0 0</pose>
        <geometry>
          <mesh>
            <scale>1 1 1</scale>
            <uri>model://abb_irb4600_support/meshes/irb4600_60_205/visual/link_6.dae</uri>
          </mesh>
        </geometry>
        <material>
          <diffuse>1 1 0 1</diffuse>
          <ambient>1 1 0 1</ambient>
        </material>
      </visual>
      <visual name='link_6_fixed_joint_lump__tool0_visual_1'>
        <pose>0 0 0 0 1.570796326794897 0</pose>
        <geometry>
          <box>
            <size>0.05 0.05 0.05</size>
          </box>
        </geometry>
      </visual>
      <gravity>false</gravity>
    </link>
    <plugin name='ign_ros2_control::IgnitionROS2ControlPlugin' filename='ign_ros2_control-system'>
      <parameters>/home/yangjingyun/robots/ros2_simulation/src/warehouse_manage/config/abb_irb4600_60_205.yaml</parameters>
    </plugin>
    <frame name='base_link-base' attached_to='base_link'>
      <pose>0 0 0 0 -0 0</pose>
    </frame>
    <frame name='base' attached_to='base_link-base'/>
    <frame name='link_6-tool0' attached_to='flange'>
      <pose>0 0 0 0 1.5708 0</pose>
    </frame>
    <frame name='tool0' attached_to='link_6-tool0'/>
    <frame name='joint_6-flange' attached_to='link_6'>
      <pose>0 0 0 0 -0 0</pose>
    </frame>
    <frame name='flange' attached_to='joint_6-flange'/>
  </model>
</sdf>
